<?xml version="1.0" encoding="utf-8"?>
<!-- This URDF was automatically created by SolidWorks to URDF Exporter! Originally created by Stephen Brawner (brawner@gmail.com) 
     Commit Version: 1.5.1-0-g916b5db  Build Version: 1.5.7152.31018
     For more information, please see http://wiki.ros.org/sw_urdf_exporter -->
<robot
  name="base">
  <link
    name="base">
    <inertial>
      <origin
        xyz="0.22237 0.14236 0.02517"
        rpy="0 0 0" />
      <mass
        value="9.1153" />
      <inertia
        ixx="0.080729"
        ixy="-0.00070476"
        ixz="0.0034829"
        iyy="0.19941"
        iyz="0.010062"
        izz="0.26108" />
    </inertial>
    <visual>
      <origin
        xyz="0 0 0"
        rpy="1.5707963267949 0 0" />
      <geometry>
        <mesh
          filename="package://robot_urdf/mesh/base.STL" />
      </geometry>
      <material
        name="blue">
        <color
          rgba="0.75294 0.53333 0 1" />
      </material>
    </visual>
    <collision>
      <origin
        xyz="0 0 0"
        rpy="1.5707963267949 0 0" />
      <geometry>
        <mesh
          filename="package://robot_urdf/mesh/base.STL" />
      </geometry>
    </collision>
  </link>
 <link
    name="digging_link_1">
<inertial>
      <origin
        xyz="-6.9389E-18 -1.1102E-16 0.092027"
        rpy="0 0 0" />
      <mass
        value="0.63832" />
      <inertia
        ixx="0.0020699"
        ixy="6.7763E-20"
        ixz="1.9957E-19"
        iyy="0.002085"
        iyz="1.7844E-19"
        izz="0.00040153" />
    </inertial>
    <visual>
      <origin
        xyz="0.17 0 0"
        rpy="0 0 0" />
      <geometry>
        <mesh
          filename="package://robot_urdf/mesh/digging_link_1.STL" />
      </geometry>
      <material
        name="blue">
        <color
          rgba="0 0 0.8 1" />
      </material>
    </visual>
    
    <collision>
      <origin
        xyz="0 0 0"
        rpy="0 0 0" />
      <geometry>
        <mesh
          filename="package://robot_urdf/mesh/digging_link_1.STL" />
      </geometry>
    </collision>
  </link>

  <joint
 name="base_to_digging_link_1" type="revolute">
	<axis xyz="0 0 1" />
	<limit effort="1000.0" lower="0.0" upper="1.516" velocity="0.5" />
	<origin xyz="0.17 0 0" rpy="0 0 0" />
	<parent link="base" />
    	<child link="digging_link_1" />
  </joint>

</robot>